2023-09-24 01:59:41,458 -  nornir.core -     INFO -        run() - Running task 'netmiko_send_command' with args {'command_string': 'show version'} on 2 hosts
2023-09-24 01:59:45,056 - nornir.core.task -    ERROR -      start() - Host 'devxe2': task 'netmiko_send_command' failed with traceback:
Traceback (most recent call last):
  File "/Library/Frameworks/Python.framework/Versions/3.10/lib/python3.10/site-packages/netmiko/base_connection.py", line 1046, in establish_connection
    self.remote_conn_pre.connect(**ssh_connect_params)
  File "/Library/Frameworks/Python.framework/Versions/3.10/lib/python3.10/site-packages/paramiko/client.py", line 485, in connect
    self._auth(
  File "/Library/Frameworks/Python.framework/Versions/3.10/lib/python3.10/site-packages/paramiko/client.py", line 818, in _auth
    raise saved_exception
  File "/Library/Frameworks/Python.framework/Versions/3.10/lib/python3.10/site-packages/paramiko/client.py", line 805, in _auth
    self._transport.auth_password(username, password)
  File "/Library/Frameworks/Python.framework/Versions/3.10/lib/python3.10/site-packages/paramiko/transport.py", line 1587, in auth_password
    return self.auth_handler.wait_for_response(my_event)
  File "/Library/Frameworks/Python.framework/Versions/3.10/lib/python3.10/site-packages/paramiko/auth_handler.py", line 263, in wait_for_response
    raise e
paramiko.ssh_exception.AuthenticationException: Authentication failed.

During handling of the above exception, another exception occurred:

Traceback (most recent call last):
  File "/Library/Frameworks/Python.framework/Versions/3.10/lib/python3.10/site-packages/nornir/core/task.py", line 99, in start
    r = self.task(self, **self.params)
  File "/Library/Frameworks/Python.framework/Versions/3.10/lib/python3.10/site-packages/nornir_netmiko/tasks/netmiko_send_command.py", line 26, in netmiko_send_command
    net_connect = task.host.get_connection(CONNECTION_NAME, task.nornir.config)
  File "/Library/Frameworks/Python.framework/Versions/3.10/lib/python3.10/site-packages/nornir/core/inventory.py", line 494, in get_connection
    self.open_connection(
  File "/Library/Frameworks/Python.framework/Versions/3.10/lib/python3.10/site-packages/nornir/core/inventory.py", line 546, in open_connection
    conn_obj.open(
  File "/Library/Frameworks/Python.framework/Versions/3.10/lib/python3.10/site-packages/nornir_netmiko/connections/netmiko.py", line 59, in open
    connection = ConnectHandler(**parameters)
  File "/Library/Frameworks/Python.framework/Versions/3.10/lib/python3.10/site-packages/netmiko/ssh_dispatcher.py", line 365, in ConnectHandler
    return ConnectionClass(*args, **kwargs)
  File "/Library/Frameworks/Python.framework/Versions/3.10/lib/python3.10/site-packages/netmiko/base_connection.py", line 439, in __init__
    self._open()
  File "/Library/Frameworks/Python.framework/Versions/3.10/lib/python3.10/site-packages/netmiko/base_connection.py", line 444, in _open
    self.establish_connection()
  File "/Library/Frameworks/Python.framework/Versions/3.10/lib/python3.10/site-packages/netmiko/base_connection.py", line 1083, in establish_connection
    raise NetmikoAuthenticationException(msg)
netmiko.exceptions.NetmikoAuthenticationException: Authentication to device failed.

Common causes of this problem are:
1. Invalid username and password
2. Incorrect SSH-key file
3. Connecting to the wrong device

Device settings: cisco_ios sandbox-iosxe-recomm-1.cisco.com:22


Authentication failed.

2023-09-24 01:59:50,562 -  nornir.core -     INFO -        run() - Running task 'netmiko_send_command' with args {'command_string': 'show version'} on 2 hosts
2023-09-24 01:59:54,032 - nornir.core.task -    ERROR -      start() - Host 'devxe2': task 'netmiko_send_command' failed with traceback:
Traceback (most recent call last):
  File "/Library/Frameworks/Python.framework/Versions/3.10/lib/python3.10/site-packages/netmiko/base_connection.py", line 1046, in establish_connection
    self.remote_conn_pre.connect(**ssh_connect_params)
  File "/Library/Frameworks/Python.framework/Versions/3.10/lib/python3.10/site-packages/paramiko/client.py", line 485, in connect
    self._auth(
  File "/Library/Frameworks/Python.framework/Versions/3.10/lib/python3.10/site-packages/paramiko/client.py", line 818, in _auth
    raise saved_exception
  File "/Library/Frameworks/Python.framework/Versions/3.10/lib/python3.10/site-packages/paramiko/client.py", line 805, in _auth
    self._transport.auth_password(username, password)
  File "/Library/Frameworks/Python.framework/Versions/3.10/lib/python3.10/site-packages/paramiko/transport.py", line 1587, in auth_password
    return self.auth_handler.wait_for_response(my_event)
  File "/Library/Frameworks/Python.framework/Versions/3.10/lib/python3.10/site-packages/paramiko/auth_handler.py", line 263, in wait_for_response
    raise e
paramiko.ssh_exception.AuthenticationException: Authentication failed.

During handling of the above exception, another exception occurred:

Traceback (most recent call last):
  File "/Library/Frameworks/Python.framework/Versions/3.10/lib/python3.10/site-packages/nornir/core/task.py", line 99, in start
    r = self.task(self, **self.params)
  File "/Library/Frameworks/Python.framework/Versions/3.10/lib/python3.10/site-packages/nornir_netmiko/tasks/netmiko_send_command.py", line 26, in netmiko_send_command
    net_connect = task.host.get_connection(CONNECTION_NAME, task.nornir.config)
  File "/Library/Frameworks/Python.framework/Versions/3.10/lib/python3.10/site-packages/nornir/core/inventory.py", line 494, in get_connection
    self.open_connection(
  File "/Library/Frameworks/Python.framework/Versions/3.10/lib/python3.10/site-packages/nornir/core/inventory.py", line 546, in open_connection
    conn_obj.open(
  File "/Library/Frameworks/Python.framework/Versions/3.10/lib/python3.10/site-packages/nornir_netmiko/connections/netmiko.py", line 59, in open
    connection = ConnectHandler(**parameters)
  File "/Library/Frameworks/Python.framework/Versions/3.10/lib/python3.10/site-packages/netmiko/ssh_dispatcher.py", line 365, in ConnectHandler
    return ConnectionClass(*args, **kwargs)
  File "/Library/Frameworks/Python.framework/Versions/3.10/lib/python3.10/site-packages/netmiko/base_connection.py", line 439, in __init__
    self._open()
  File "/Library/Frameworks/Python.framework/Versions/3.10/lib/python3.10/site-packages/netmiko/base_connection.py", line 444, in _open
    self.establish_connection()
  File "/Library/Frameworks/Python.framework/Versions/3.10/lib/python3.10/site-packages/netmiko/base_connection.py", line 1083, in establish_connection
    raise NetmikoAuthenticationException(msg)
netmiko.exceptions.NetmikoAuthenticationException: Authentication to device failed.

Common causes of this problem are:
1. Invalid username and password
2. Incorrect SSH-key file
3. Connecting to the wrong device

Device settings: cisco_ios sandbox-iosxe-recomm-1.cisco.com:22


Authentication failed.

2023-09-24 10:54:38,680 -  nornir.core -     INFO -        run() - Running task 'netmiko_send_command' with args {'command_string': 'show version'} on 2 hosts
2023-09-24 10:54:42,344 - nornir.core.task -    ERROR -      start() - Host 'devxe2': task 'netmiko_send_command' failed with traceback:
Traceback (most recent call last):
  File "/Library/Frameworks/Python.framework/Versions/3.10/lib/python3.10/site-packages/netmiko/base_connection.py", line 1046, in establish_connection
    self.remote_conn_pre.connect(**ssh_connect_params)
  File "/Library/Frameworks/Python.framework/Versions/3.10/lib/python3.10/site-packages/paramiko/client.py", line 485, in connect
    self._auth(
  File "/Library/Frameworks/Python.framework/Versions/3.10/lib/python3.10/site-packages/paramiko/client.py", line 818, in _auth
    raise saved_exception
  File "/Library/Frameworks/Python.framework/Versions/3.10/lib/python3.10/site-packages/paramiko/client.py", line 805, in _auth
    self._transport.auth_password(username, password)
  File "/Library/Frameworks/Python.framework/Versions/3.10/lib/python3.10/site-packages/paramiko/transport.py", line 1587, in auth_password
    return self.auth_handler.wait_for_response(my_event)
  File "/Library/Frameworks/Python.framework/Versions/3.10/lib/python3.10/site-packages/paramiko/auth_handler.py", line 263, in wait_for_response
    raise e
paramiko.ssh_exception.AuthenticationException: Authentication failed.

During handling of the above exception, another exception occurred:

Traceback (most recent call last):
  File "/Library/Frameworks/Python.framework/Versions/3.10/lib/python3.10/site-packages/nornir/core/task.py", line 99, in start
    r = self.task(self, **self.params)
  File "/Library/Frameworks/Python.framework/Versions/3.10/lib/python3.10/site-packages/nornir_netmiko/tasks/netmiko_send_command.py", line 26, in netmiko_send_command
    net_connect = task.host.get_connection(CONNECTION_NAME, task.nornir.config)
  File "/Library/Frameworks/Python.framework/Versions/3.10/lib/python3.10/site-packages/nornir/core/inventory.py", line 494, in get_connection
    self.open_connection(
  File "/Library/Frameworks/Python.framework/Versions/3.10/lib/python3.10/site-packages/nornir/core/inventory.py", line 546, in open_connection
    conn_obj.open(
  File "/Library/Frameworks/Python.framework/Versions/3.10/lib/python3.10/site-packages/nornir_netmiko/connections/netmiko.py", line 59, in open
    connection = ConnectHandler(**parameters)
  File "/Library/Frameworks/Python.framework/Versions/3.10/lib/python3.10/site-packages/netmiko/ssh_dispatcher.py", line 365, in ConnectHandler
    return ConnectionClass(*args, **kwargs)
  File "/Library/Frameworks/Python.framework/Versions/3.10/lib/python3.10/site-packages/netmiko/base_connection.py", line 439, in __init__
    self._open()
  File "/Library/Frameworks/Python.framework/Versions/3.10/lib/python3.10/site-packages/netmiko/base_connection.py", line 444, in _open
    self.establish_connection()
  File "/Library/Frameworks/Python.framework/Versions/3.10/lib/python3.10/site-packages/netmiko/base_connection.py", line 1083, in establish_connection
    raise NetmikoAuthenticationException(msg)
netmiko.exceptions.NetmikoAuthenticationException: Authentication to device failed.

Common causes of this problem are:
1. Invalid username and password
2. Incorrect SSH-key file
3. Connecting to the wrong device

Device settings: cisco_ios sandbox-iosxe-recomm-1.cisco.com:22


Authentication failed.

2023-09-24 11:16:15,088 -  nornir.core -     INFO -        run() - Running task 'netmiko_send_command' with args {'command_string': 'show version'} on 2 hosts
2023-09-24 11:16:18,725 - nornir.core.task -    ERROR -      start() - Host 'devxe2': task 'netmiko_send_command' failed with traceback:
Traceback (most recent call last):
  File "/Library/Frameworks/Python.framework/Versions/3.10/lib/python3.10/site-packages/netmiko/base_connection.py", line 1046, in establish_connection
    self.remote_conn_pre.connect(**ssh_connect_params)
  File "/Library/Frameworks/Python.framework/Versions/3.10/lib/python3.10/site-packages/paramiko/client.py", line 485, in connect
    self._auth(
  File "/Library/Frameworks/Python.framework/Versions/3.10/lib/python3.10/site-packages/paramiko/client.py", line 818, in _auth
    raise saved_exception
  File "/Library/Frameworks/Python.framework/Versions/3.10/lib/python3.10/site-packages/paramiko/client.py", line 805, in _auth
    self._transport.auth_password(username, password)
  File "/Library/Frameworks/Python.framework/Versions/3.10/lib/python3.10/site-packages/paramiko/transport.py", line 1587, in auth_password
    return self.auth_handler.wait_for_response(my_event)
  File "/Library/Frameworks/Python.framework/Versions/3.10/lib/python3.10/site-packages/paramiko/auth_handler.py", line 263, in wait_for_response
    raise e
paramiko.ssh_exception.AuthenticationException: Authentication failed.

During handling of the above exception, another exception occurred:

Traceback (most recent call last):
  File "/Library/Frameworks/Python.framework/Versions/3.10/lib/python3.10/site-packages/nornir/core/task.py", line 99, in start
    r = self.task(self, **self.params)
  File "/Library/Frameworks/Python.framework/Versions/3.10/lib/python3.10/site-packages/nornir_netmiko/tasks/netmiko_send_command.py", line 26, in netmiko_send_command
    net_connect = task.host.get_connection(CONNECTION_NAME, task.nornir.config)
  File "/Library/Frameworks/Python.framework/Versions/3.10/lib/python3.10/site-packages/nornir/core/inventory.py", line 494, in get_connection
    self.open_connection(
  File "/Library/Frameworks/Python.framework/Versions/3.10/lib/python3.10/site-packages/nornir/core/inventory.py", line 546, in open_connection
    conn_obj.open(
  File "/Library/Frameworks/Python.framework/Versions/3.10/lib/python3.10/site-packages/nornir_netmiko/connections/netmiko.py", line 59, in open
    connection = ConnectHandler(**parameters)
  File "/Library/Frameworks/Python.framework/Versions/3.10/lib/python3.10/site-packages/netmiko/ssh_dispatcher.py", line 365, in ConnectHandler
    return ConnectionClass(*args, **kwargs)
  File "/Library/Frameworks/Python.framework/Versions/3.10/lib/python3.10/site-packages/netmiko/base_connection.py", line 439, in __init__
    self._open()
  File "/Library/Frameworks/Python.framework/Versions/3.10/lib/python3.10/site-packages/netmiko/base_connection.py", line 444, in _open
    self.establish_connection()
  File "/Library/Frameworks/Python.framework/Versions/3.10/lib/python3.10/site-packages/netmiko/base_connection.py", line 1083, in establish_connection
    raise NetmikoAuthenticationException(msg)
netmiko.exceptions.NetmikoAuthenticationException: Authentication to device failed.

Common causes of this problem are:
1. Invalid username and password
2. Incorrect SSH-key file
3. Connecting to the wrong device

Device settings: cisco_ios sandbox-iosxe-recomm-1.cisco.com:22


Authentication failed.

2023-09-24 11:16:46,973 -  nornir.core -     INFO -        run() - Running task 'netmiko_send_command' with args {'command_string': 'show version'} on 2 hosts
2023-09-24 11:26:21,343 -  nornir.core -     INFO -        run() - Running task 'netmiko_send_command' with args {'command_string': 'sh ip int brief'} on 2 hosts
2023-09-24 11:29:42,266 -  nornir.core -     INFO -        run() - Running task 'netmiko_send_command' with args {'command_string': 'sh ip int brief'} on 2 hosts
2023-09-24 11:31:16,519 -  nornir.core -     INFO -        run() - Running task 'netmiko_send_command' with args {'command_string': 'show version'} on 2 hosts
2023-09-24 11:32:55,717 -  nornir.core -     INFO -        run() - Running task 'netmiko_send_config' with args {'config_commands': ['interface gi0/0', 'description Interface description set by silvester nornirtest']} on 2 hosts
2023-09-24 11:33:44,193 -  nornir.core -     INFO -        run() - Running task 'netmiko_send_config' with args {'config_commands': ['interface gi0/0', 'description Interface description set by silvester nornirtest']} on 2 hosts
2023-09-24 11:34:33,646 -  nornir.core -     INFO -        run() - Running task 'netmiko_send_command' with args {'command_string': 'show version'} on 2 hosts
2023-09-24 11:44:37,244 -  nornir.core -     INFO -        run() - Running task 'netmiko_send_config' with args {'config_commands': ['interface gi0/0', 'description Test interface Dont touch']} on 2 hosts
2023-09-24 11:45:04,961 -  nornir.core -     INFO -        run() - Running task 'netmiko_send_config' with args {'config_commands': ['interface gi1', 'description Test interface Dont touch']} on 2 hosts
2023-09-24 11:47:27,605 -  nornir.core -  WARNING -        run() - Task 'napalm_get' has not been run – 0 hosts selected
2023-09-24 11:47:52,546 -  nornir.core -  WARNING -        run() - Task 'napalm_get' has not been run – 0 hosts selected
2023-09-24 11:48:22,448 -  nornir.core -  WARNING -        run() - Task 'napalm_get' has not been run – 0 hosts selected
2023-09-24 11:48:45,909 -  nornir.core -     INFO -        run() - Running task 'napalm_get' with args {'getters': ['get_facts']} on 2 hosts
2023-09-24 11:49:06,127 -  nornir.core -     INFO -        run() - Running task 'napalm_get' with args {'getters': ['interfaces']} on 2 hosts
2023-09-24 11:51:22,674 -  nornir.core -  WARNING -        run() - Task 'napalm_cli' has not been run – 0 hosts selected
2023-09-24 11:54:54,052 -  nornir.core -  WARNING -        run() - Task 'napalm_cli' has not been run – 0 hosts selected
2023-09-24 11:55:37,851 -  nornir.core -  WARNING -        run() - Task 'napalm_cli' has not been run – 0 hosts selected
2023-09-24 11:55:58,801 -  nornir.core -  WARNING -        run() - Task 'napalm_cli' has not been run – 0 hosts selected
2023-09-24 12:12:18,518 -  nornir.core -  WARNING -        run() - Task 'napalm_cli' has not been run – 0 hosts selected
2023-09-24 12:12:34,989 -  nornir.core -  WARNING -        run() - Task 'napalm_cli' has not been run – 0 hosts selected
2023-09-24 12:13:01,883 -  nornir.core -  WARNING -        run() - Task 'napalm_cli' has not been run – 0 hosts selected
2023-09-24 12:13:12,140 -  nornir.core -  WARNING -        run() - Task 'napalm_cli' has not been run – 0 hosts selected
2023-09-24 12:14:51,303 -  nornir.core -  WARNING -        run() - Task 'napalm_cli' has not been run – 0 hosts selected
2023-09-24 12:16:04,153 -  nornir.core -  WARNING -        run() - Task 'napalm_cli' has not been run – 0 hosts selected
2023-09-24 12:18:23,506 -  nornir.core -  WARNING -        run() - Task 'napalm_cli' has not been run – 0 hosts selected
2023-09-24 12:18:40,416 -  nornir.core -  WARNING -        run() - Task 'napalm_cli' has not been run – 0 hosts selected
2023-09-24 12:19:27,591 -  nornir.core -  WARNING -        run() - Task 'napalm_cli' has not been run – 0 hosts selected
2023-09-24 12:19:32,498 -  nornir.core -  WARNING -        run() - Task 'napalm_cli' has not been run – 0 hosts selected
2023-09-24 12:22:01,732 -  nornir.core -     INFO -        run() - Running task 'napalm_cli' with args {'commands': ['sh ver', 'sh ip int brief']} on 1 hosts
